<?xml version="1.0" encoding="utf-8"?>
<!-- This URDF was automatically created by SolidWorks to URDF Exporter! Originally created by Stephen Brawner (brawner@gmail.com) 
     Commit Version: 1.6.0-1-g15f4949  Build Version: 1.6.7594.29634
     For more information, please see http://wiki.ros.org/sw_urdf_exporter -->
<robot
  name="my_robot_description">
  <link
    name="base_link">
    <inertial>
      <origin
        xyz="3.70875526496076E-17 0.0475569232950614 -2.62262926339617E-17"
        rpy="0 0 0" />
      <mass
        value="1.45942477796077" />
      <inertia
        ixx="0.008806043561622"
        ixy="2.5780187411334E-18"
        ixz="-2.22346148654254E-18"
        iyy="0.019970262326728"
        iyz="-1.25760725434254E-18"
        izz="0.0166714401279268" />
    </inertial>
    <visual>
      <origin
        xyz="0 0 0"
        rpy="0 0 0" />
      <geometry>
        <mesh
          filename="package://my_robot_description/meshes/base_link.STL" />
      </geometry>
      <material
        name="">
        <color
          rgba="0.792156862745098 0.819607843137255 0.933333333333333 1" />
      </material>
    </visual>
    <collision>
      <origin
        xyz="0 0 0"
        rpy="0 0 0" />
      <geometry>
        <mesh
          filename="package://my_robot_description/meshes/base_link.STL" />
      </geometry>
    </collision>
  </link>
  <link
    name="left_front_wheel_link">
    <inertial>
      <origin
        xyz="0 -0.0281275303643724 -5.20417042793042E-18"
        rpy="0 0 0" />
      <mass
        value="0.0969966731795849" />
      <inertia
        ixx="9.38005213215944E-05"
        ixy="-1.12237458356287E-36"
        ixz="1.95021298162857E-36"
        iyy="0.000167618694284579"
        iyz="1.0179478791177E-20"
        izz="9.38005213215945E-05" />
    </inertial>
    <visual>
      <origin
        xyz="0 0 0"
        rpy="0 0 0" />
      <geometry>
        <mesh
          filename="package://my_robot_description/meshes/left_front_wheel_link.STL" />
      </geometry>
      <material
        name="">
        <color
          rgba="0.792156862745098 0.819607843137255 0.933333333333333 1" />
      </material>
    </visual>
    <collision>
      <origin
        xyz="0 0 0"
        rpy="0 0 0" />
      <geometry>
        <mesh
          filename="package://my_robot_description/meshes/left_front_wheel_link.STL" />
      </geometry>
    </collision>
  </link>
  <joint
    name="left_front_wheel_joint"
    type="continuous">
    <origin
      xyz="-0.1375 -0.1 -0.01"
      rpy="0 0 0" />
    <parent
      link="base_link" />
    <child
      link="left_front_wheel_link" />
    <axis
      xyz="0 1 0" />
    <limit
      effort="100"
      velocity="100" />
  </joint>
  <link
    name="right_front_wheel_link">
    <inertial>
      <origin
        xyz="0 -0.0281275303643724 1.38777878078145E-17"
        rpy="0 0 0" />
      <mass
        value="0.0969966731795849" />
      <inertia
        ixx="9.38005213215944E-05"
        ixy="-1.12237458356287E-36"
        ixz="1.95021298162857E-36"
        iyy="0.000167618694284579"
        iyz="1.0179478791177E-20"
        izz="9.38005213215945E-05" />
    </inertial>
    <visual>
      <origin
        xyz="0 0 0"
        rpy="0 0 0" />
      <geometry>
        <mesh
          filename="package://my_robot_description/meshes/right_front_wheel_link.STL" />
      </geometry>
      <material
        name="">
        <color
          rgba="0.792156862745098 0.819607843137255 0.933333333333333 1" />
      </material>
    </visual>
    <collision>
      <origin
        xyz="0 0 0"
        rpy="0 0 0" />
      <geometry>
        <mesh
          filename="package://my_robot_description/meshes/right_front_wheel_link.STL" />
      </geometry>
    </collision>
  </link>
  <joint
    name="right_front_wheel_joint"
    type="continuous">
    <origin
      xyz="-0.1375 0.1 -0.01"
      rpy="3.1416 0 0" />
    <parent
      link="base_link" />
    <child
      link="right_front_wheel_link" />
    <axis
      xyz="0 1 0" />
    <limit
      effort="100"
      velocity="100" />
  </joint>
  <link
    name="left_back_wheel_link">
    <inertial>
      <origin
        xyz="0 -0.0281275303643724 -3.46944695195361E-18"
        rpy="0 0 0" />
      <mass
        value="0.0969966731795849" />
      <inertia
        ixx="9.38005213215944E-05"
        ixy="-1.12237458356287E-36"
        ixz="1.95021298162857E-36"
        iyy="0.000167618694284579"
        iyz="1.0179478791177E-20"
        izz="9.38005213215945E-05" />
    </inertial>
    <visual>
      <origin
        xyz="0 0 0"
        rpy="0 0 0" />
      <geometry>
        <mesh
          filename="package://my_robot_description/meshes/left_back_wheel_link.STL" />
      </geometry>
      <material
        name="">
        <color
          rgba="0.792156862745098 0.819607843137255 0.933333333333333 1" />
      </material>
    </visual>
    <collision>
      <origin
        xyz="0 0 0"
        rpy="0 0 0" />
      <geometry>
        <mesh
          filename="package://my_robot_description/meshes/left_back_wheel_link.STL" />
      </geometry>
    </collision>
  </link>
  <joint
    name="left_back_wheel_joint"
    type="continuous">
    <origin
      xyz="0.1375 -0.1 -0.01"
      rpy="0 0 0" />
    <parent
      link="base_link" />
    <child
      link="left_back_wheel_link" />
    <axis
      xyz="0 1 0" />
    <limit
      effort="100"
      velocity="100" />
  </joint>
  <link
    name="right_back_wheel_link">
    <inertial>
      <origin
        xyz="0 -0.0281275303643724 1.38777878078145E-17"
        rpy="0 0 0" />
      <mass
        value="0.0969966731795849" />
      <inertia
        ixx="9.38005213215944E-05"
        ixy="-1.12237458356287E-36"
        ixz="1.95021298162857E-36"
        iyy="0.000167618694284579"
        iyz="1.0179478791177E-20"
        izz="9.38005213215945E-05" />
    </inertial>
    <visual>
      <origin
        xyz="0 0 0"
        rpy="0 0 0" />
      <geometry>
        <mesh
          filename="package://my_robot_description/meshes/right_back_wheel_link.STL" />
      </geometry>
      <material
        name="">
        <color
          rgba="0.792156862745098 0.819607843137255 0.933333333333333 1" />
      </material>
    </visual>
    <collision>
      <origin
        xyz="0 0 0"
        rpy="0 0 0" />
      <geometry>
        <mesh
          filename="package://my_robot_description/meshes/right_back_wheel_link.STL" />
      </geometry>
    </collision>
  </link>
  <joint
    name="right_back_wheel_joint"
    type="continuous">
    <origin
      xyz="0.1375 0.1 -0.01"
      rpy="3.1416 0 0" />
    <parent
      link="base_link" />
    <child
      link="right_back_wheel_link" />
    <axis
      xyz="0 1 0" />
    <limit
      effort="100"
      velocity="100" />
  </joint>
</robot>