<?xml version="1.0" encoding="utf-8"?>
<!-- This URDF was automatically created by SolidWorks to URDF Exporter! Originally created by Stephen Brawner (brawner@gmail.com) 
     Commit Version: 1.6.0-1-g15f4949  Build Version: 1.6.7594.29634
     For more information, please see http://wiki.ros.org/sw_urdf_exporter -->
<robot
  name="my_robot_description">
  <link
    name="base_link">
    <inertial>
      <origin
        xyz="0.1 0.15 -0.051716902185961"
        rpy="0 0 0" />
      <mass
        value="1.26542477796077" />
      <inertia
        ixx="0.0126045884497173"
        ixy="2.39154458701331E-17"
        ixz="1.21561119962974E-17"
        iyy="0.00722763131212556"
        iyz="-2.18546204604467E-18"
        izz="0.0146393895646815" />
    </inertial>
    <visual>
      <origin
        xyz="0 0 0"
        rpy="0 0 0" />
      <geometry>
        <mesh
          filename="package://my_robot_description/meshes/base_link.STL" />
      </geometry>
      <material
        name="">
        <color
          rgba="0.792156862745098 0.819607843137255 0.933333333333333 1" />
      </material>
    </visual>
    <collision>
      <origin
        xyz="0 0 0"
        rpy="0 0 0" />
      <geometry>
        <mesh
          filename="package://my_robot_description/meshes/base_link.STL" />
      </geometry>
    </collision>
  </link>
  <link
    name="leftfront_wheel_link">
    <inertial>
      <origin
        xyz="0 -0.0281275303643725 2.77555756156289E-17"
        rpy="0 0 0" />
      <mass
        value="0.0969966731795849" />
      <inertia
        ixx="9.38005213215944E-05"
        ixy="-1.12237458356287E-36"
        ixz="1.95021298162857E-36"
        iyy="0.000167618694284579"
        iyz="4.53259247614831E-21"
        izz="9.38005213215944E-05" />
    </inertial>
    <visual>
      <origin
        xyz="0 0 0"
        rpy="0 0 0" />
      <geometry>
        <mesh
          filename="package://my_robot_description/meshes/leftfront_wheel_link.STL" />
      </geometry>
      <material
        name="">
        <color
          rgba="0.792156862745098 0.819607843137255 0.933333333333333 1" />
      </material>
    </visual>
    <collision>
      <origin
        xyz="0 0 0"
        rpy="0 0 0" />
      <geometry>
        <mesh
          filename="package://my_robot_description/meshes/leftfront_wheel_link.STL" />
      </geometry>
    </collision>
  </link>
  <joint
    name="leftfront_wheel_joint"
    type="continuous">
    <origin
      xyz="0 0.115 0.25"
      rpy="1.5708 1.5708 0" />
    <parent
      link="base_link" />
    <child
      link="leftfront_wheel_link" />
    <axis
      xyz="0 1 0" />
    <limit
      effort="100"
      velocity="100" />
  </joint>
  <link
    name="rightfront_wheel_link">
    <inertial>
      <origin
        xyz="0 -0.0281275303643725 -1.38777878078145E-17"
        rpy="0 0 0" />
      <mass
        value="0.0969966731795849" />
      <inertia
        ixx="9.38005213215943E-05"
        ixy="-1.12237458356287E-36"
        ixz="1.95021298162857E-36"
        iyy="0.000167618694284579"
        iyz="1.0179478791177E-20"
        izz="9.38005213215944E-05" />
    </inertial>
    <visual>
      <origin
        xyz="0 0 0"
        rpy="0 0 0" />
      <geometry>
        <mesh
          filename="package://my_robot_description/meshes/rightfront_wheel_link.STL" />
      </geometry>
      <material
        name="">
        <color
          rgba="0.792156862745098 0.819607843137255 0.933333333333333 1" />
      </material>
    </visual>
    <collision>
      <origin
        xyz="0 0 0"
        rpy="0 0 0" />
      <geometry>
        <mesh
          filename="package://my_robot_description/meshes/rightfront_wheel_link.STL" />
      </geometry>
    </collision>
  </link>
  <joint
    name="rightfront_wheel_joint"
    type="continuous">
    <origin
      xyz="0.2 0.115 0.25"
      rpy="1.5708 -1.5708 0" />
    <parent
      link="base_link" />
    <child
      link="rightfront_wheel_link" />
    <axis
      xyz="0 1 0" />
    <limit
      effort="100"
      velocity="100" />
  </joint>
  <link
    name="leftback_wheel_link">
    <inertial>
      <origin
        xyz="0 -0.0281275303643725 4.16333634234434E-17"
        rpy="0 0 0" />
      <mass
        value="0.0969966731795849" />
      <inertia
        ixx="9.38005213215944E-05"
        ixy="-1.12237458356287E-36"
        ixz="1.95021298162857E-36"
        iyy="0.000167618694284579"
        iyz="4.53259247614831E-21"
        izz="9.38005213215944E-05" />
    </inertial>
    <visual>
      <origin
        xyz="0 0 0"
        rpy="0 0 0" />
      <geometry>
        <mesh
          filename="package://my_robot_description/meshes/leftback_wheel_link.STL" />
      </geometry>
      <material
        name="">
        <color
          rgba="0.792156862745098 0.819607843137255 0.933333333333333 1" />
      </material>
    </visual>
    <collision>
      <origin
        xyz="0 0 0"
        rpy="0 0 0" />
      <geometry>
        <mesh
          filename="package://my_robot_description/meshes/leftback_wheel_link.STL" />
      </geometry>
    </collision>
  </link>
  <joint
    name="leftback_wheel_joint"
    type="continuous">
    <origin
      xyz="0 0.115 0.05"
      rpy="1.5708 1.5708 0" />
    <parent
      link="base_link" />
    <child
      link="leftback_wheel_link" />
    <axis
      xyz="0 1 0" />
    <limit
      effort="100"
      velocity="100" />
  </joint>
  <link
    name="rightback_wheel_link">
    <inertial>
      <origin
        xyz="-6.93889390390723E-18 -0.0281275303643725 0"
        rpy="0 0 0" />
      <mass
        value="0.0969966731795849" />
      <inertia
        ixx="9.38005213215943E-05"
        ixy="-1.12237458356287E-36"
        ixz="1.95021298162857E-36"
        iyy="0.000167618694284579"
        iyz="1.0179478791177E-20"
        izz="9.38005213215944E-05" />
    </inertial>
    <visual>
      <origin
        xyz="0 0 0"
        rpy="0 0 0" />
      <geometry>
        <mesh
          filename="package://my_robot_description/meshes/rightback_wheel_link.STL" />
      </geometry>
      <material
        name="">
        <color
          rgba="0.792156862745098 0.819607843137255 0.933333333333333 1" />
      </material>
    </visual>
    <collision>
      <origin
        xyz="0 0 0"
        rpy="0 0 0" />
      <geometry>
        <mesh
          filename="package://my_robot_description/meshes/rightback_wheel_link.STL" />
      </geometry>
    </collision>
  </link>
  <joint
    name="rightback_wheel_joint"
    type="continuous">
    <origin
      xyz="0.2 0.115 0.05"
      rpy="1.5708 -1.5708 0" />
    <parent
      link="base_link" />
    <child
      link="rightback_wheel_link" />
    <axis
      xyz="0 1 0" />
    <limit
      effort="100"
      velocity="100" />
  </joint>
</robot>